Workbook

Sheet 00_Übersicht
A1: WÖk Master Items v1.4 FINAL – führende Register- und Governance-Fassung
A2: Stand 16.08.2026 · 621 WÖk-IDs · Begriffsleitfaden v1.5 · SDG+ explizit gekennzeichnet · leere Eingaben bleiben unbewertet · aktive Benchmarks strikt von Legacy-Werten getrennt
A4: Qualitätskennzahlen | F4: Nutzung und Freigabelogik
A6: WÖk-IDs | B6: =COUNTA('01_Item_Register'!A5:A625) -> 621 | C6: Eindeutige Regeln | D6: =COUNTA('03_Scoring_Rules'!A5:A32) -> 28 | F6: 1 | G6: Messwerte werden ausschließlich in 06_Scorecards (Spalte J) eingetragen.
A7: Indikatorfamilien | B7: 204 | C7: Korrigierte #N/A-Zeilen | D7: 320 | F7: 2 | G7: Qualitative oder hybride Regeln benötigen einen nachweisgebundenen Assurance-Score in Spalte K.
A8: Benchmarkabhängig | B8: =COUNTIF('01_Item_Register'!K5:K625,"Benchmarkabhängig") -> 72 | C8: Qualitative Regeln | D8: =COUNTIF('01_Item_Register'!K5:K625,"Qualitativ") -> 54 | F8: 3 | G8: Ein Benchmark wirkt erst, wenn er in 02_Benchmarks vollständig befüllt und auf „Aktiv“ gesetzt ist.
A9: Rechtsgrenzen | B9: =COUNTIF('01_Item_Register'!K5:K625,"Rechts-/Genehmigungsgrenze") -> 10 | C9: Offene −2/−3-Grenzen | D9: =COUNTIF('01_Item_Register'!K5:K625,"Unvollständige Grenzauflösung") -> 10 | F9: 4 | G9: Der FinalScore ist das strengste vorhandene Ergebnis; positive Werte kompensieren keine schlechteren Werte.
F10: 5 | G10: Kritische oder offene Fachlogik ist im Register und Prüfprotokoll gekennzeichnet und nicht automatisch freigegeben.
A12: Schwellenkategorien | F12: Prüfprioritäten
A14: Feste WÖk-Kalibrierung | B14: =COUNTIF('01_Item_Register'!K5:K625,A14) -> 415 | F14: Kritisch | G14: =COUNTIF('01_Item_Register'!AC5:AC625,F14) -> 126
A15: Feste WÖk-Grobkalibrierung | B15: =COUNTIF('01_Item_Register'!K5:K625,A15) -> 48 | F15: Hoch | G15: =COUNTIF('01_Item_Register'!AC5:AC625,F15) -> 168
A16: Benchmarkabhängig | B16: =COUNTIF('01_Item_Register'!K5:K625,A16) -> 72 | F16: Mittel | G16: =COUNTIF('01_Item_Register'!AC5:AC625,F16) -> 327
A17: Qualitativ | B17: =COUNTIF('01_Item_Register'!K5:K625,A17) -> 54
A18: Rechts-/Genehmigungsgrenze | B18: =COUNTIF('01_Item_Register'!K5:K625,A18) -> 10 | F18: Release-Status
A19: Produktspezifische Indexkalibrierung | B19: =COUNTIF('01_Item_Register'!K5:K625,A19) -> 12 | F19: v1.4 FINAL = führende technische Registerfassung
A20: Unvollständige Grenzauflösung | B20: =COUNTIF('01_Item_Register'!K5:K625,A20) -> 10 | F20: Offene Kalibrierungen bleiben ausdrücklich offen
F21: FINAL bedeutet nicht: alle Schwellen extern validiert
A23: Navigation
A25: 01_Item_Register | B25: Vollständiges Register, Quellen-, NACE-, Qualitäts- und Prüfstatus
A26: 02_Benchmarks | B26: Aktive validierte Benchmarks getrennt von Legacy-Werten
A27: 03_Scoring_Rules | B27: 28 normalisierte Regelmuster und offene Kalibrierungen
A28: 04_Tarifmodell | B28: Aktives WÖk-Arbeitsmodell und historische Referenz
A29: 06_Scorecards | B29: Eingabe, automatische Bewertung, FinalScore und Steuersatz
A30: 07_Quellenkatalog | B30: Offizielle und interne Referenzquellen mit Funktion
A31: 08_Prüfprotokoll | B31: Befunde, Korrekturen und verbleibende Fachaufgaben
A32: 09_Methodik_Transparenz | B32: Trennung politischer Richtungsbewertung, Scorecard, Evidenz und Rechenlogik
A33: 10_Public_Export_Schema | B33: Verbindliches Schema für öffentlichen Register-Viewer und Downloads

Sheet 01_Item_Register
A1: 01 · WÖk-ID-Register v1.4 FINAL
A2: 621 eindeutige WÖk-IDs · 162 explizite SDG+-Zuordnungen · Quellenfunktion, Schwellenstatus, NACE-Migration, Systemgrenze, Datenqualität, Assurance und Prüfpriorität
A4: WOK_ID | B4: SDG_or_SDGplus | C4: Target/Unterziel | D4: Indikatorfamilie | E4: Item | F4: Definition/Messgröße | G4: Einheit | H4: Polarity | I4: Rule_ID | J4: Schwellen (WÖk-Klassen) | K4: Schwellenkategorie | L4: Schwellenstatus | M4: Grenzwertbasis | N4: Benchmarkbedarf | O4: Quelle_kurz | P4: Quelle_detail | Q4: Quellenfunktion | R4: Quellenstatus | S4: Source_IDs | T4: NACE_Beispiele_Legacy | U4: NACE_Version | V4: NACE_Rev2.1_Beispiele | W4: NACE_Status | X4: Systemgrenze | Y4: Berechnungslogik | Z4: Datenqualitätsanforderung | AA4: Assurance_Anforderung | AB4: Fachlogik_Status | AC4: Prüfpriorität | AD4: Prüfhinweis | AE4: Version | AF4: Gültig_ab | AG4: Gültig_bis
A5: WOK-S-101 | B5: SDG 1 – Keine Armut | C5: 1.2 | D5: Faire Arbeit & Einkommen | E5: Faire Arbeit & Einkommen – Living Wage | F5: Abdeckung Lebenslohn | G5: % Beschäftigte | H5: higher_is_better | I5: R27 | J5: ≥95:+3; 80–94:+2; 60–79:0; 40–59:‑2; <40:‑3 | K5: Feste WÖk-Kalibrierung | L5: Arbeitskalibrierung – fachlich zu validieren | M5: WÖk-interne Klassenlogik | N5: Optional/Nein | O5: ESRS S1; GRI 401/403/405/406 | P5: ESRS S1, GRI 401/403/405/406, ILO | Q5: Mess-, Berichts- oder Managementrahmen; Schwellen sind grundsätzlich WÖk-Kalibrierungen | R5: Messgrundlage belegt; Schwellenkalibrierung offen | S5: EU-ESRS; GRI; ISO-45001; ILO-LW; ILO-CORE | T5: G47 Handel; K Versicherungen; M72 F&E | U5: Legacy / nicht explizit versioniert | W5: Migration auf NACE Rev. 2.1 erforderlich | X5: Eigene Belegschaft/Organisation; FTE, Beschäftigtengruppe und Zeitraum | Y5: Anteil Beschäftigte ≥ Living Wage (zertifizierte Methodik). | Z5: Primärdaten bevorzugt; Sekundärdaten nur transparent und versioniert; Methode und Systemgrenze dokumentieren | AA5: Limited Assurance; risikobasiert höhere Prüftiefe | AB5: Strukturell nutzbar; Schwellen fachlich zu validieren | AC5: Mittel | AD5: Vollständige fünfstufige numerische Regel. | AE5: v1.4 | AF5: 2026-08-16
A6: WOK-S-102 | B6: SDG 1 – Keine Armut | C6: 1.2 | D6: Faire Arbeit & Einkommen | E6: Faire Arbeit & Einkommen – Tarifbindung | F6: Beschäftigte unter Kollektivvertrag | G6: % | H6: higher_is_better | I6: R26 | J6: ≥90:+3; 70–89:+2; 50–69:0; 30–49:‑2; <30:‑3 | K6: Feste WÖk-Kalibrierung | L6: Arbeitskalibrierung – fachlich zu validieren | M6: WÖk-interne Klassenlogik | N6: Optional/Nein | O6: ESRS S1; GRI 401/403/405/406 | P6: ESRS S1, GRI 401/403/405/406, ILO | Q6: Mess-, Berichts- oder Managementrahmen; Schwellen sind grundsätzlich WÖk-Kalibrierungen | R6: Messgrundlage belegt; Schwellenkalibrierung offen | S6: EU-ESRS; GRI; ISO-45001; ILO-LW; ILO-CORE | T6: G47 Handel; K Versicherungen; M72 F&E | U6: Legacy / nicht explizit versioniert | W6: Migration auf NACE Rev. 2.1 erforderlich | X6: Eigene Belegschaft/Organisation; FTE, Beschäftigtengruppe und Zeitraum | Y6: Quote = Zähler / Nenner gemäß Quelle; in %. | Z6: Primärdaten bevorzugt; Sekundärdaten nur transparent und versioniert; Methode und Systemgrenze dokumentieren | AA6: Limited Assurance; risikobasiert höhere Prüftiefe | AB6: Strukturell nutzbar; Schwellen fachlich zu validieren | AC6: Mittel | AD6: Vollständige fünfstufige numerische Regel. | AE6: v1.4 | AF6: 2026-08-16
A7: WOK-S-103 | B7: SDG 1 – Keine Armut | C7: 1.2 | D7: Faire Arbeit & Einkommen | E7: Faire Arbeit & Einkommen – LTIFR | F7: Arbeitsunfälle pro Mio Stunden | G7: Unfälle/Mio Std. | H7: lower_is_better | I7: R02 | J7: 0:+3; ≤1:+2; ≤3:0; ≤5:‑2; >5:‑3 | K7: Feste WÖk-Kalibrierung | L7: Arbeitskalibrierung – fachlich zu validieren | M7: WÖk-interne Klassenlogik | N7: Optional/Nein | O7: ESRS S1; GRI 401/403/405/406 | P7: ESRS S1, GRI 401/403/405/406, ILO | Q7: Mess-, Berichts- oder Managementrahmen; Schwellen sind grundsätzlich WÖk-Kalibrierungen | R7: Messgrundlage belegt; Schwellenkalibrierung offen | S7: EU-ESRS; GRI; ISO-45001; ILO-LW; ILO-CORE | T7: G47 Handel; K Versicherungen; M72 F&E | U7: Legacy / nicht explizit versioniert | W7: Migration auf NACE Rev. 2.1 erforderlich | X7: Eigene Belegschaft/Organisation; FTE, Beschäftigtengruppe und Zeitraum | Y7: LTIFR = Unfälle mit Ausfallzeit / 1 Mio. Std. (ILO/GRI 403). | Z7: Primärdaten bevorzugt; Sekundärdaten nur transparent und versioniert; Methode und Systemgrenze dokumentieren | AA7: Limited Assurance; risikobasiert höhere Prüftiefe | AB7: Strukturell nutzbar; Schwellen fachlich zu validieren | AC7: Mittel | AD7: Vollständige fünfstufige numerische Regel. | AE7: v1.4 | AF7: 2026-08-16
A8: WOK-S-104 | B8: SDG 1 – Keine Armut | C8: 1.3 | D8: Sozialschutz & Benefits | E8: Sozialschutz & Benefits – Living Wage | F8: Abdeckung Lebenslohn | G8: % Beschäftigte | H8: higher_is_better | I8: R27 | J8: ≥95:+3; 80–94:+2; 60–79:0; 40–59:‑2; <40:‑3 | K8: Feste WÖk-Kalibrierung | L8: Arbeitskalibrierung – fachlich zu validieren | M8: WÖk-interne Klassenlogik | N8: Optional/Nein | O8: ESRS S1; GRI 401/403/405/406 | P8: ESRS S1, GRI 401/403/405/406, ILO | Q8: Mess-, Berichts- oder Managementrahmen; Schwellen sind grundsätzlich WÖk-Kalibrierungen | R8: Messgrundlage belegt; Schwellenkalibrierung offen | S8: EU-ESRS; GRI; ISO-45001; ILO-LW; ILO-CORE | T8: G47 Handel; K Versicherungen; M72 F&E | U8: Legacy / nicht explizit versioniert | W8: Migration auf NACE Rev. 2.1 erforderlich | X8: Eigene Belegschaft/Organisation; FTE, Beschäftigtengruppe und Zeitraum | Y8: Anteil Beschäftigte ≥ Living Wage (zertifizierte Methodik). | Z8: Primärdaten bevorzugt; Sekundärdaten nur transparent und versioniert; Methode und Systemgrenze dokumentieren | AA8: Limited Assurance; risikobasiert höhere Prüftiefe | AB8: Strukturell nutzbar; Schwellen fachlich zu validieren | AC8: Mittel | AD8: Vollständige fünfstufige numerische Regel. | AE8: v1.4 | AF8: 2026-08-16
A9: WOK-S-105 | B9: SDG 1 – Keine Armut | C9: 1.3 | D9: Sozialschutz & Benefits | E9: Sozialschutz & Benefits – Tarifbindung | F9: Beschäftigte unter Kollektivvertrag | G9: % | H9: higher_is_better | I9: R26 | J9: ≥90:+3; 70–89:+2; 50–69:0; 30–49:‑2; <30:‑3 | K9: Feste WÖk-Kalibrierung | L9: Arbeitskalibrierung – fachlich zu validieren | M9: WÖk-interne Klassenlogik | N9: Optional/Nein | O9: ESRS S1; GRI 401/403/405/406 | P9: ESRS S1, GRI 401/403/405/406, ILO | Q9: Mess-, Berichts- oder Managementrahmen; Schwellen sind grundsätzlich WÖk-Kalibrierungen | R9: Messgrundlage belegt; Schwellenkalibrierung offen | S9: EU-ESRS; GRI; ISO-45001; ILO-LW; ILO-CORE | T9: G47 Handel; K Versicherungen; M72 F&E | U9: Legacy / nicht explizit versioniert | W9: Migration auf NACE Rev. 2.1 erforderlich | X9: Eigene Belegschaft/Organisation; FTE, Beschäftigtengruppe und Zeitraum | Y9: Quote = Zähler / Nenner gemäß Quelle; in %. | Z9: Primärdaten bevorzugt; Sekundärdaten nur transparent und versioniert; Methode und Systemgrenze dokumentieren | AA9: Limited Assurance; risikobasiert höhere Prüftiefe | AB9: Strukturell nutzbar; Schwellen fachlich zu validieren | AC9: Mittel | AD9: Vollständige fünfstufige numerische Regel. | AE9: v1.4 | AF9: 2026-08-16
A10: WOK-S-106 | B10: SDG 1 – Keine Armut | C10: 1.3 | D10: Sozialschutz & Benefits | E10: Sozialschutz & Benefits – LTIFR | F10: Arbeitsunfälle pro Mio Stunden | G10: Unfälle/Mio Std. | H10: lower_is_better | I10: R02 | J10: 0:+3; ≤1:+2; ≤3:0; ≤5:‑2; >5:‑3 | K10: Feste WÖk-Kalibrierung | L10: Arbeitskalibrierung – fachlich zu validieren | M10: WÖk-interne Klassenlogik | N10: Optional/Nein | O10: ESRS S1; GRI 401/403/405/406 | P10: ESRS S1, GRI 401/403/405/406, ILO | Q10: Mess-, Berichts- oder Managementrahmen; Schwellen sind grundsätzlich WÖk-Kalibrierungen | R10: Messgrundlage belegt; Schwellenkalibrierung offen | S10: EU-ESRS; GRI; ISO-45001; ILO-LW; ILO-CORE | T10: G47 Handel; K Versicherungen; M72 F&E | U10: Legacy / nicht explizit versioniert | W10: Migration auf NACE Rev. 2.1 erforderlich | X10: Eigene Belegschaft/Organisation; FTE, Beschäftigtengruppe und Zeitraum | Y10: LTIFR = Unfälle mit Ausfallzeit / 1 Mio. Std. (ILO/GRI 403). | Z10: Primärdaten bevorzugt; Sekundärdaten nur transparent und versioniert; Methode und Systemgrenze dokumentieren | AA10: Limited Assurance; risikobasiert höhere Prüftiefe | AB10: Strukturell nutzbar; Schwellen fachlich zu validieren | AC10: Mittel | AD10: Vollständige fünfstufige numerische Regel. | AE10: v1.4 | AF10: 2026-08-16
A11: WOK-SC-101 | B11: SDG 1 – Keine Armut | C11: 1.2 | D11: Living‑Wage in Lieferkette | E11: Living‑Wage in Lieferkette – ESG‑Spend‑Coverage | F11: Anteil verifizierter ESG‑Daten am Spend | G11: % | H11: higher_is_better | I11: R26 | J11: ≥90:+3; 70–89:+2; 50–69:0; 30–49:‑2; <30:‑3 | K11: Feste WÖk-Kalibrierung | L11: Arbeitskalibrierung – fachlich zu validieren | M11: WÖk-interne Klassenlogik | N11: Optional/Nein | O11: ESRS S2; GRI 308/414/408/409 | P11: ESRS S2, GRI 308/414, OECD Due Diligence | Q11: Mess-, Berichts- oder Managementrahmen; Schwellen sind grundsätzlich WÖk-Kalibrierungen | R11: Messgrundlage belegt; Schwellenkalibrierung offen | S11: EU-ESRS; GRI; OECD-DD; ILO-CORE | T11: C20 Chemie; C24 Stahl; C29 Fahrzeuge | U11: Legacy / nicht explizit versioniert | W11: Migration auf NACE Rev. 2.1 erforderlich | X11: Vorgelagerte Lieferkette; relevante Tier-Stufen und Beschaffungsvolumen | Y11: Quote = Zähler / Nenner gemäß Quelle; in %. | Z11: Primärdaten bevorzugt; Sekundärdaten nur transparent und versioniert; Methode und Systemgrenze dokumentieren | AA11: Limited Assurance; risikobasiert höhere Prüftiefe | AB11: Strukturell nutzbar; Schwellen fachlich zu validieren | AC11: Mittel | AD11: Vollständige fünfstufige numerische Regel. | AE11: v1.4 | AF11: 2026-08-16
A12: WOK-SC-102 | B12: SDG 1 – Keine Armut | C12: 1.2 | D12: Living‑Wage in Lieferkette | E12: Living‑Wage in Lieferkette – Kinder/Zwangsarbeit | F12: Audits ohne Verstöße | G12: % Lieferanten | H12: higher_is_better | I12: R28 | J12: ≥98:+3; 90–97:+2; 75–89:0; 50–74:‑2; <50:‑3 | K12: Feste WÖk-Kalibrierung | L12: Arbeitskalibrierung – fachlich zu validieren | M12: WÖk-interne Klassenlogik | N12: Optional/Nein | O12: ESRS S2; GRI 308/414/408/409 | P12: ESRS S2, GRI 308/414, OECD Due Diligence | Q12: Mess-, Berichts- oder Managementrahmen; Schwellen sind grundsätzlich WÖk-Kalibrierungen | R12: Messgrundlage belegt; Schwellenkalibrierung offen | S12: EU-ESRS; GRI; OECD-DD; ILO-CORE | T12: C20 Chemie; C24 Stahl; C29 Fahrzeuge | U12: Legacy / nicht explizit versioniert | W12: Migration auf NACE Rev. 2.1 erforderlich | X12: Vorgelagerte Lieferkette; relevante Tier-Stufen und Beschaffungsvolumen | Y12: Quote = Zähler / Nenner gemäß Quelle; in %. | Z12: Primärdaten bevorzugt; Sekundärdaten nur transparent und versioniert; Methode und Systemgrenze dokumentieren | AA12: Limited Assurance; risikobasiert höhere Prüftiefe | AB12: Strukturell nutzbar; Schwellen fachlich zu validieren | AC12: Mittel | AD12: Vollständige fünfstufige numerische Regel. | AE12: v1.4 | AF12: 2026-08-16
A13: WOK-SC-103 | B13: SDG 1 – Keine Armut | C13: 1.2 | D13: Living‑Wage in Lieferkette | E13: Living‑Wage in Lieferkette – Scope‑3 Daten | F13: Primärdaten‑Abdeckung | G13: % Kategorien | H13: higher_is_better | I13: R23 | J13: ≥80:+3; 60–79:+2; 40–59:0; 20–39:‑2; <20:‑3 | K13: Feste WÖk-Kalibrierung | L13: Arbeitskalibrierung – fachlich zu validieren | M13: WÖk-interne Klassenlogik | N13: Optional/Nein | O13: ESRS E1; GHG Protocol | P13: ESRS E1, GHG Protocol (Corporate/Scope 1–3), ISO 14064/14067 | Q13: Mess-, Berichts- oder Managementrahmen; Schwellen sind grundsätzlich WÖk-Kalibrierungen | R13: Messgrundlage belegt; Schwellenkalibrierung offen | S13: EU-ESRS; GHG-CORP; GHG-S3; GHG-PROD | T13: C20 Chemie; C24 Stahl; C29 Fahrzeuge | U13: Legacy / nicht explizit versioniert | W13: Migration auf NACE Rev. 2.1 erforderlich | X13: Vorgelagerte Lieferkette; relevante Tier-Stufen und Beschaffungsvolumen | Y13: Quote = Zähler / Nenner gemäß Quelle; in %. | Z13: Primärdaten bevorzugt; Sekundärdaten nur transparent und versioniert; Methode und Systemgrenze dokumentieren | AA13: Limited Assurance; risikobasiert höhere Prüftiefe | AB13: Strukturell nutzbar; Schwellen fachlich zu validieren | AC13: Mittel | AD13: Vollständige fünfstufige numerische Regel. | AE13: v1.4 | AF13: 2026-08-16
A14: WOK-G-101 | B14: SDG 1 – Keine Armut | C14: 1.b | D14: Pay Ratio & Fairness | E14: Pay Ratio & Fairness – Antikorruption | F14: Bestätigte Fälle/1.000 FTE | G14: Fälle/1.000 FTE | H14: lower_is_better | I14: R01 | J14: 0:+3; ≤0,2:+2; ≤0,5:0; ≤1:‑2; >1:‑3 | K14: Feste WÖk-Kalibrierung | L14: Arbeitskalibrierung – fachlich zu validieren | M14: WÖk-interne Klassenlogik | N14: Optional/Nein | O14: ESRS G1; GRI 205/207 | P14: ESRS G1, GRI 205/207, OECD Anti‑Bribery | Q14: Mess-, Berichts- oder Managementrahmen; Schwellen sind grundsätzlich WÖk-Kalibrierungen | R14: Messgrundlage belegt; Schwellenkalibrierung offen | S14: EU-ESRS; GRI; OECD-AB | T14: G47 Handel; K Versicherungen; M72 F&E | U14: Legacy / nicht explizit versioniert | W14: Migration auf NACE Rev. 2.1 erforderlich | X14: Organisation/Governance; konsolidierter Kreis und relevante Rechtseinheiten | Y14: Siehe Quelle: Definition gemäß Standard (ESRS/GRI/Taxonomie/ISO). | Z14: Primärdaten bevorzugt; Sekundärdaten nur transparent und versioniert; Methode und Systemgrenze dokumentieren | AA14: Limited Assurance; risikobasiert höhere Prüftiefe | AB14: Strukturell nutzbar; Schwellen fachlich zu validieren | AC14: Mittel | AD14: Vollständige fünfstufige numerische Regel. | AE14: v1.4 | AF14: 2026-08-16
A15: WOK-G-102 | B15: SDG 1 – Keine Armut | C15: 1.b | D15: Pay Ratio & Fairness | E15: Pay Ratio & Fairness – Whistleblowing | F15: Wirksamkeits‑Score | G15: 0–1 | H15: higher_is_better | I15: R16 | J15: ≥0,9:+3; 0,75–0,89:+2; 0,6–0,74:0; 0,4–0,59:‑2; <0,4:‑3 | K15: Feste WÖk-Kalibrierung | L15: Arbeitskalibrierung – fachlich zu validieren | M15: WÖk-interne Klassenlogik | N15: Optional/Nein | O15: ESRS G1; GRI 205/207 | P15: ESRS G1, GRI 205/207, OECD Anti‑Bribery | Q15: Mess-, Berichts- oder Managementrahmen; Schwellen sind grundsätzlich WÖk-Kalibrierungen | R15: Messgrundlage belegt; Schwellenkalibrierung offen | S15: EU-ESRS; GRI; OECD-AB | T15: G47 Handel; K Versicherungen; M72 F&E | U15: Legacy / nicht explizit versioniert | W15: Migration auf NACE Rev. 2.1 erforderlich | X15: Organisation/Governance; konsolidierter Kreis und relevante Rechtseinheiten | Y15: Siehe Quelle: Definition gemäß Standard (ESRS/GRI/Taxonomie/ISO). | Z15: Primärdaten bevorzugt; Sekundärdaten nur transparent und versioniert; Methode und Systemgrenze dokumentieren | AA15: Limited Assurance; risikobasiert höhere Prüftiefe | AB15: Strukturell nutzbar; Schwellen fachlich zu validieren | AC15: Mittel | AD15: Vollständige fünfstufige numerische Regel. | AE15: v1.4 | AF15: 2026-08-16
A16: WOK-G-103 | B16: SDG 1 – Keine Armut | C16: 1.b | D16: Pay Ratio & Fairness | E16: Pay Ratio & Fairness – Steuertransparenz | F16: CbCR‑Offenlegung | G16: 0–1 | H16: higher_is_better | I16: R08 | J16: vollständig:+3; teilweise:+2; minimal:0; schlecht:‑2 | K16: Qualitativ | L16: Assurance und Kriterienkatalog erforderlich | M16: WÖk-interne Kategorien | N16: Optional/Nein | O16: ESRS G1; GRI 205/207 | P16: ESRS G1, GRI 205/207, OECD Anti‑Bribery | Q16: Mess-, Berichts- oder Managementrahmen; Schwellen sind grundsätzlich WÖk-Kalibrierungen | R16: Messgrundlage belegt; Schwellenkalibrierung offen | S16: EU-ESRS; GRI; OECD-AB | T16: G47 Handel; K Versicherungen; M72 F&E | U16: Legacy / nicht explizit versioniert | W16: Migration auf NACE Rev. 2.1 erforderlich | X16: Organisation/Governance; konsolidierter Kreis und relevante Rechtseinheiten | Y16: Siehe Quelle: Definition gemäß Standard (ESRS/GRI/Taxonomie/ISO). | Z16: Dokumentierter Kriterienkatalog; nachvollziehbare Evidenz; DQR A/B bevorzugt | AA16: Unabhängige Fachprüfung/Limited Assurance; bei roten Linien Reasonable Assurance | AB16: Prüfung/Parametrisierung erforderlich | AC16: Hoch | AD16: Die Kategorie −3 fehlt; Vollständigkeit und Wirksamkeit sind feldspezifisch zu definieren. | AE16: v1.4 | AF16: 2026-08-16
... A625: WOK-SYS-220 | B625: SDG+ – Transparenz/Open Data | C625: — | D625: Publikations‑Backlog (OA) | E625: Publikations‑Backlog (OA) – Kooperationen | F625: aktive, evaluierte Partnerschaften/Jahr | G625: #/Jahr | H625: higher_is_better | I625: R20 | J625: ≥5:+3; 3–4:+2; 1–2:0; 0:‑2 | K625: Feste WÖk-Grobkalibrierung | L625: Klasse −3 nur für negative/unzulässige Werte ergänzt | M625: WÖk-interne Grobkalibrierung | N625: Optional/Nein | O625: SROI/SDG17 | P625: SDG 16/17, WJP, V‑Dem | Q625: Methodischer Platzhalter; konkrete Fach- und Primärdatenquelle erforderlich | R625: Platzhalter – fachliche Operationalisierung offen | S625: INT-WOEK-TSROI; SVI-SROI; UN-SDG | T625: G47 Handel; K Versicherungen; M72 F&E | U625: Legacy / nicht explizit versioniert | W625: Migration auf NACE Rev. 2.1 erforderlich | X625: Programm/Portfolio/Systemraum; Empfängergruppe, Region und Zeitraum explizit definieren | Y625: Siehe Quelle: Definition gemäß Standard (ESRS/GRI/Taxonomie/ISO). | Z625: Primärdaten bevorzugt; Sekundärdaten nur transparent und versioniert; Methode und Systemgrenze dokumentieren | AA625: Limited Assurance; risikobasiert höhere Prüftiefe | AB625: Fachlogik nicht abschließend operationalisiert | AC625: Kritisch | AD625: SROI/SDG 17 ist keine hinreichend konkrete Mess- oder Schwellenquelle. Für sachlogisch nichtnegative Zählwerte ist 0 die schlechteste reguläre Klasse (−2). | AE625: v1.4 | AF625: 2026-08-16

Sheet 02_Benchmarks
A1: 02 · Benchmarks und Referenzwerte
A2: Aktive Benchmarks werden nur nach dokumentierter Validierung genutzt. Q:T enthalten ausschließlich Legacy-Rechenwerte aus v1.2 und wirken nicht auf den FinalScore.
A4: WOK_ID | B4: NACE_Legacy | C4: NACE_Version | D4: Region | E4: Tech/Klasse | F4: Einheit | G4: Polarity | H4: Rule_ID | I4: Benchmarkbedarf | J4: Active_BM_Best | K4: Active_BM_Neutral | L4: Active_BM_Warn | M4: Active_BM_Critical | N4: Active_Source_ID | O4: Gültig_ab | P4: Active_Status | Q4: Legacy_BM_Neutral | R4: Legacy_BM_150pct | S4: Legacy_BM_250pct | T4: Legacy_Source | U4: Prüfhinweis
A5: WOK-S-101 | B5: G47 | C5: Legacy / Migration auf NACE Rev. 2.1 offen | D5: EU | F5: % Beschäftigte | G5: higher_is_better | H5: R27 | I5: Optional/Nein | P5: Optional – kein aktiver Benchmark | Q5: 69.5 | R5: 100 | S5: 100 | T5: threshold:0-class | U5: Legacy-Werte bleiben nur als historische Rechenhilfe erhalten und werden nicht für den FinalScore verwendet.
A6: WOK-S-102 | B6: G47 | C6: Legacy / Migration auf NACE Rev. 2.1 offen | D6: EU | F6: % | G6: higher_is_better | H6: R26 | I6: Optional/Nein | P6: Optional – kein aktiver Benchmark | Q6: 59.5 | R6: 89.25 | S6: 100 | T6: threshold:0-class | U6: Legacy-Werte bleiben nur als historische Rechenhilfe erhalten und werden nicht für den FinalScore verwendet.
A7: WOK-S-103 | B7: G47 | C7: Legacy / Migration auf NACE Rev. 2.1 offen | D7: EU | F7: Unfälle/Mio Std. | G7: lower_is_better | H7: R02 | I7: Optional/Nein | P7: Optional – kein aktiver Benchmark | Q7: 3 | R7: 4.5 | S7: 7.5 | T7: threshold:0-class | U7: Legacy-Werte bleiben nur als historische Rechenhilfe erhalten und werden nicht für den FinalScore verwendet.
A8: WOK-S-104 | B8: G47 | C8: Legacy / Migration auf NACE Rev. 2.1 offen | D8: EU | F8: % Beschäftigte | G8: higher_is_better | H8: R27 | I8: Optional/Nein | P8: Optional – kein aktiver Benchmark | Q8: 69.5 | R8: 100 | S8: 100 | T8: threshold:0-class | U8: Legacy-Werte bleiben nur als historische Rechenhilfe erhalten und werden nicht für den FinalScore verwendet.
A9: WOK-S-105 | B9: G47 | C9: Legacy / Migration auf NACE Rev. 2.1 offen | D9: EU | F9: % | G9: higher_is_better | H9: R26 | I9: Optional/Nein | P9: Optional – kein aktiver Benchmark | Q9: 59.5 | R9: 89.25 | S9: 100 | T9: threshold:0-class | U9: Legacy-Werte bleiben nur als historische Rechenhilfe erhalten und werden nicht für den FinalScore verwendet.
A10: WOK-S-106 | B10: G47 | C10: Legacy / Migration auf NACE Rev. 2.1 offen | D10: EU | F10: Unfälle/Mio Std. | G10: lower_is_better | H10: R02 | I10: Optional/Nein | P10: Optional – kein aktiver Benchmark | Q10: 3 | R10: 4.5 | S10: 7.5 | T10: threshold:0-class | U10: Legacy-Werte bleiben nur als historische Rechenhilfe erhalten und werden nicht für den FinalScore verwendet.
A11: WOK-SC-101 | B11: C20 | C11: Legacy / Migration auf NACE Rev. 2.1 offen | D11: EU | F11: % | G11: higher_is_better | H11: R26 | I11: Optional/Nein | P11: Optional – kein aktiver Benchmark | Q11: 59.5 | R11: 89.25 | S11: 100 | T11: threshold:0-class | U11: Legacy-Werte bleiben nur als historische Rechenhilfe erhalten und werden nicht für den FinalScore verwendet.
A12: WOK-SC-102 | B12: C20 | C12: Legacy / Migration auf NACE Rev. 2.1 offen | D12: EU | F12: % Lieferanten | G12: higher_is_better | H12: R28 | I12: Optional/Nein | P12: Optional – kein aktiver Benchmark | Q12: 82 | R12: 100 | S12: 100 | T12: threshold:0-class | U12: Legacy-Werte bleiben nur als historische Rechenhilfe erhalten und werden nicht für den FinalScore verwendet.
A13: WOK-SC-103 | B13: C20 | C13: Legacy / Migration auf NACE Rev. 2.1 offen | D13: EU | F13: % Kategorien | G13: higher_is_better | H13: R23 | I13: Optional/Nein | P13: Optional – kein aktiver Benchmark | Q13: 49.5 | R13: 74.25 | S13: 100 | T13: threshold:0-class | U13: Legacy-Werte bleiben nur als historische Rechenhilfe erhalten und werden nicht für den FinalScore verwendet.
A14: WOK-G-101 | B14: G47 | C14: Legacy / Migration auf NACE Rev. 2.1 offen | D14: EU | F14: Fälle/1.000 FTE | G14: lower_is_better | H14: R01 | I14: Optional/Nein | P14: Optional – kein aktiver Benchmark | Q14: 0.5 | R14: 0.75 | S14: 1.25 | T14: threshold:0-class | U14: Legacy-Werte bleiben nur als historische Rechenhilfe erhalten und werden nicht für den FinalScore verwendet.
A15: WOK-G-102 | B15: G47 | C15: Legacy / Migration auf NACE Rev. 2.1 offen | D15: EU | F15: 0–1 | G15: higher_is_better | H15: R16 | I15: Optional/Nein | P15: Optional – kein aktiver Benchmark | Q15: 0.67 | R15: 1 | S15: 1 | T15: threshold:0-class | U15: Legacy-Werte bleiben nur als historische Rechenhilfe erhalten und werden nicht für den FinalScore verwendet.
A16: WOK-G-103 | B16: G47 | C16: Legacy / Migration auf NACE Rev. 2.1 offen | D16: EU | F16: 0–1 | G16: higher_is_better | H16: R08 | I16: Optional/Nein | P16: Optional – kein aktiver Benchmark | Q16: 0.5 | R16: 0.75 | S16: 0.9 | T16: default:higher_is_better_abs | U16: Legacy-Werte bleiben nur als historische Rechenhilfe erhalten und werden nicht für den FinalScore verwendet.
... A625: WOK-SYS-220 | B625: G47 | C625: Legacy / Migration auf NACE Rev. 2.1 offen | D625: EU | F625: #/Jahr | G625: higher_is_better | H625: R20 | I625: Optional/Nein | P625: Optional – kein aktiver Benchmark | Q625: 1.5 | R625: 2.25 | S625: 3.75 | T625: threshold:0-class | U625: Legacy-Werte bleiben nur als historische Rechenhilfe erhalten und werden nicht für den FinalScore verwendet.

Sheet 03_Scoring_Rules
A1: 03 · Scoring Rules
A2: 28 normalisierte Schwellenmuster. v1.4 ändert keine Schwellen stillschweigend: numerische Regeln bleiben versioniert; qualitative und benchmarkabhängige Regeln verlangen eigene Evidenz.
A4: Rule_ID | B4: Schwelle_original | C4: Regeltyp | D4: Richtung | E4: Eingabemodus | F4: B1 | G4: B2 | H4: B3 | I4: B4 | J4: S1 | K4: S2 | L4: S3 | M4: S4 | N4: S5 | O4: Schwellenkategorie | P4: Status | Q4: Grenzwertbasis | R4: Hinweis | S4: Anzahl_Items
A5: R01 | B5: 0:+3; ≤0,2:+2; ≤0,5:0; ≤1:‑2; >1:‑3 | C5: NUM_LOW | D5: Niedriger ist besser | E5: Numerischer Messwert | F5: 0 | G5: 0.2 | H5: 0.5 | I5: 1 | J5: 3 | K5: 2 | L5: 0 | M5: -2 | N5: -3 | O5: Feste WÖk-Kalibrierung | P5: Arbeitskalibrierung – fachlich zu validieren | Q5: WÖk-interne Klassenlogik | R5: Vollständige fünfstufige numerische Regel. | S5: 46
A6: R02 | B6: 0:+3; ≤1:+2; ≤3:0; ≤5:‑2; >5:‑3 | C6: NUM_LOW | D6: Niedriger ist besser | E6: Numerischer Messwert | F6: 0 | G6: 1 | H6: 3 | I6: 5 | J6: 3 | K6: 2 | L6: 0 | M6: -2 | N6: -3 | O6: Feste WÖk-Kalibrierung | P6: Arbeitskalibrierung – fachlich zu validieren | Q6: WÖk-interne Klassenlogik | R6: Vollständige fünfstufige numerische Regel. | S6: 30
A7: R03 | B7: Net Gain:+3; No Net Loss:0; Net Loss:‑2/‑3 | C7: QUALITATIVE | D7: Qualitative Klassen | E7: Assurance-Score (−3…+3) | O7: Qualitativ | P7: Assurance und Kriterienkatalog erforderlich | Q7: WÖk-Kategorien; fachliche Definition je Wirkungsfeld | R7: Net Gain/No Net Loss/Net Loss ist ohne feldspezifischen Nachweis nicht automatisierbar. | S7: 8
A8: R04 | B8: SBTi 1,5°C:+3; <2°C:+2; Branchenmittel:0; >150%:‑2; >250%:‑3 | C8: MANUAL_HYBRID | D8: Zielpfad/Benchmark | E8: Assurance-Score (−3…+3) | O8: Benchmarkabhängig | P8: SBTi-Validierung und Branchenbenchmark erforderlich | Q8: SBTi-Zielvalidierung plus Branchenbenchmark | R8: Zielstatus und tatsächliche Performance müssen getrennt geprüft werden. | S8: 2
A9: R05 | B9: Top 15%:+3; +15–30%:+2; +31–60%:0; >+60%:‑2/‑3 | C9: BENCHMARK | D9: Benchmarkabhängig | E9: Messwert + aktiver Benchmark | O9: Benchmarkabhängig | P9: Validierter Benchmark fehlt | Q9: Branche/Region/Technologie | R9: Die Grenze >+60 % ist derzeit nicht eindeutig in −2/−3 aufgelöst. | S9: 9
A10: R06 | B10: Top‑10%:+3; Mittel:0; >150%:‑2; >250%:‑3 | C10: BENCHMARK | D10: Benchmarkabhängig | E10: Messwert + aktiver Benchmark | O10: Benchmarkabhängig | P10: Validierter Benchmark fehlt | Q10: Branche/Region/Technologie | R10: Top-10-Prozent, Mittelwert, 150 % und 250 % müssen aus einer dokumentierten Grundgesamtheit stammen. | S10: 49
A11: R07 | B11: Top‑10%:+3; ±Benchmark:0; >150%:‑2; >250%:‑3 | C11: BENCHMARK | D11: Benchmarkabhängig | E11: Messwert + aktiver Benchmark | O11: Benchmarkabhängig | P11: Validierter Benchmark fehlt | Q11: Produktgruppe/Region/Technologie | R11: Produktspezifische Referenzpopulation erforderlich. | S11: 12
A12: R08 | B12: vollständig:+3; teilweise:+2; minimal:0; schlecht:‑2 | C12: QUALITATIVE | D12: Qualitative Klassen | E12: Assurance-Score (−3…+3) | O12: Qualitativ | P12: Assurance und Kriterienkatalog erforderlich | Q12: WÖk-interne Kategorien | R12: Die Kategorie −3 fehlt; Vollständigkeit und Wirksamkeit sind feldspezifisch zu definieren. | S12: 46
A13: R09 | B13: ≤1,2:+3; 1,21–1,4:+2; 1,41–1,6:0; 1,61–1,8:‑2; >1,8:‑3 | C13: NUM_LOW | D13: Niedriger ist besser | E13: Numerischer Messwert | F13: 1.2 | G13: 1.4 | H13: 1.6 | I13: 1.8 | J13: 3 | K13: 2 | L13: 0 | M13: -2 | N13: -3 | O13: Feste WÖk-Kalibrierung | P13: Messstandard belegt; Klassen sind WÖk-Kalibrierung | Q13: PUE-Messung nach ISO/IEC 30134-2; Klassen intern | R13: Klimazone und Rechenzentrumstyp sind bei der Validierung zu berücksichtigen. | S13: 9
A14: R10 | B14: ≤100:+3; 101–250:0; >250:‑2 | C14: NUM_LOW | D14: Niedriger ist besser | E14: Numerischer Messwert | F14: 100 | G14: 250 | H14: 1e+99 | I14: 1e+99 | J14: 3 | K14: 0 | L14: -2 | M14: -2 | N14: -2 | O14: Feste WÖk-Grobkalibrierung | P14: Klassen +2 und −3 fehlen | Q14: WÖk-interne Grobkalibrierung | R14: Automatik bildet nur die explizit vorhandenen Klassen ab. | S14: 8
A15: R11 | B15: ≤2:+3; ≤5:+2; ≤8:0; >8:‑2/‑3 | C15: NUM_LOW | D15: Niedriger ist besser | E15: Numerischer Messwert | F15: 2 | G15: 5 | H15: 8 | I15: 1e+99 | J15: 3 | K15: 2 | L15: 0 | M15: -2 | N15: -2 | O15: Unvollständige Grenzauflösung | P15: Grenze zwischen −2 und −3 offen | Q15: WÖk-Arbeitskalibrierung | R15: Werte >8 werden bis zur Fachentscheidung konservativ mit −2 bewertet; manuelle Verschärfung über Assurance möglich. | S15: 5
A16: R12 | B16: ≤50% Grenzwert:+3; ≤75%:+2; ≤100%:0; 101–120%:‑2; >120%:‑3 | C16: LEGAL_RATIO | D16: Niedriger Anteil am Grenzwert ist besser | E16: Messwert in % des Rechts-/Genehmigungsgrenzwerts | F16: 50 | G16: 75 | H16: 100 | I16: 120 | J16: 3 | K16: 2 | L16: 0 | M16: -2 | N16: -3 | O16: Rechts-/Genehmigungsgrenze | P16: Rechtsfundstelle je Fall erforderlich | Q16: Jeweils anwendbare Rechtsnorm/Genehmigung | R16: Nicht der absolute Messwert, sondern Messwert ÷ Grenzwert × 100 wird bewertet. | S16: 10
A17: R13 | B17: ≤5:+3; 6–10:+2; 11–20:0; 21–30:‑2; >30:‑3 | C17: NUM_LOW | D17: Niedriger ist besser | E17: Numerischer Messwert | F17: 5 | G17: 10 | H17: 20 | I17: 30 | J17: 3 | K17: 2 | L17: 0 | M17: -2 | N17: -3 | O17: Feste WÖk-Kalibrierung | P17: Arbeitskalibrierung – fachlich zu validieren | Q17: WÖk-interne Klassenlogik | R17: Vollständige fünfstufige numerische Regel. | S17: 40
A18: R14 | B18: ≥0,8:+3; 0,6–0,79:+2; 0,4–0,59:0; 0,2–0,39:‑2; <0,2:‑3 | C18: NUM_HIGH | D18: Höher ist besser | E18: Numerischer Messwert | F18: 0.2 | G18: 0.4 | H18: 0.6 | I18: 0.8 | J18: -3 | K18: -2 | L18: 0 | M18: 2 | N18: 3 | O18: Feste WÖk-Kalibrierung | P18: Arbeitskalibrierung – fachlich zu validieren | Q18: WÖk-interne Klassenlogik | R18: Vollständige fünfstufige numerische Regel. | S18: 9
A19: R15 | B19: ≥0,8:+3; 0,7–0,79:+2; 0,6–0,69:0; 0,5–0,59:‑2; <0,5:‑3 | C19: NUM_HIGH | D19: Höher ist besser | E19: Numerischer Messwert | F19: 0.5 | G19: 0.6 | H19: 0.7 | I19: 0.8 | J19: -3 | K19: -2 | L19: 0 | M19: 2 | N19: 3 | O19: Feste WÖk-Kalibrierung | P19: Arbeitskalibrierung – fachlich zu validieren | Q19: WÖk-interne Klassenlogik | R19: Vollständige fünfstufige numerische Regel. | S19: 40
A20: R16 | B20: ≥0,9:+3; 0,75–0,89:+2; 0,6–0,74:0; 0,4–0,59:‑2; <0,4:‑3 | C20: NUM_HIGH | D20: Höher ist besser | E20: Numerischer Messwert | F20: 0.4 | G20: 0.6 | H20: 0.75 | I20: 0.9 | J20: -3 | K20: -2 | L20: 0 | M20: 2 | N20: 3 | O20: Feste WÖk-Kalibrierung | P20: Arbeitskalibrierung – fachlich zu validieren | Q20: WÖk-interne Klassenlogik | R20: Vollständige fünfstufige numerische Regel. | S20: 50
A21: R17 | B21: ≥40:+3; 25–39:+2; 10–24:0; 5–9:‑2; <5:‑3 | C21: NUM_HIGH | D21: Höher ist besser | E21: Numerischer Messwert | F21: 5 | G21: 10 | H21: 25 | I21: 40 | J21: -3 | K21: -2 | L21: 0 | M21: 2 | N21: 3 | O21: Feste WÖk-Kalibrierung | P21: Arbeitskalibrierung – fachlich zu validieren | Q21: WÖk-interne Klassenlogik | R21: Vollständige fünfstufige numerische Regel. | S21: 4
A22: R18 | B22: ≥50:+3; ≥40:+2; ≥30:0; <30:‑2/‑3 | C22: NUM_HIGH | D22: Höher ist besser | E22: Numerischer Messwert | F22: 30 | G22: 40 | H22: 50 | I22: 1e+99 | J22: -2 | K22: 0 | L22: 2 | M22: 3 | N22: 3 | O22: Unvollständige Grenzauflösung | P22: Grenze zwischen −2 und −3 offen | Q22: WÖk-Arbeitskalibrierung | R22: Werte <30 werden bis zur Fachentscheidung mit −2 bewertet; manuelle Verschärfung über Assurance möglich. | S22: 5
A23: R19 | B23: ≥5:+3; 3–4,9:+2; 1–2,9:0; 0,5–0,9:‑2; <0,5:‑3 | C23: NUM_HIGH | D23: Höher ist besser | E23: Numerischer Messwert | F23: 0.5 | G23: 1 | H23: 3 | I23: 5 | J23: -3 | K23: -2 | L23: 0 | M23: 2 | N23: 3 | O23: Feste WÖk-Kalibrierung | P23: Arbeitskalibrierung – fachlich zu validieren | Q23: WÖk-interne Klassenlogik | R23: Vollständige fünfstufige numerische Regel. | S23: 4
A24: R20 | B24: ≥5:+3; 3–4:+2; 1–2:0; 0:‑2 | C24: NUM_HIGH | D24: Höher ist besser | E24: Numerischer Messwert | F24: 0 | G24: 1 | H24: 3 | I24: 5 | J24: -3 | K24: -2 | L24: 0 | M24: 2 | N24: 3 | O24: Feste WÖk-Grobkalibrierung | P24: Klasse −3 nur für negative/unzulässige Werte ergänzt | Q24: WÖk-interne Grobkalibrierung | R24: Für sachlogisch nichtnegative Zählwerte ist 0 die schlechteste reguläre Klasse (−2). | S24: 40
... A32: R28 | B32: ≥98:+3; 90–97:+2; 75–89:0; 50–74:‑2; <50:‑3 | C32: NUM_HIGH | D32: Höher ist besser | E32: Numerischer Wert / Prozentwert gemäß Einheit | F32: 50 | G32: 75 | H32: 90 | I32: 98 | J32: -3 | K32: -2 | L32: 0 | M32: 2 | N32: 3 | O32: Feste WÖk-Kalibrierung | P32: Arbeitskalibrierung – fachlich zu validieren | Q32: WÖk-interne Klassenlogik | R32: Vollständige fünfstufige numerische Regel. | S32: 33

Sheet 04_Tarifmodell
A1: 04 · Tarifmodell
A2: Aktive Fassung: WÖk-Arbeitsmodell v1.3. Keine geltende Rechtsnorm. Historische Modelle werden separat und ohne Rechenwirkung dokumentiert.
A5: FinalScore | B5: Steuerklasse | C5: Steuersatz_pct | D5: Status | E5: Kommentar
A6: -3 | B6: Hoch schädlich | C6: 25 | D6: Aktives WÖk-Arbeitsmodell v1.3 | E6: Höchste Belastung; rote Linien und Prüfpflicht beachten.
A7: -2 | B7: Schädlich | C7: 20 | D7: Aktives WÖk-Arbeitsmodell v1.3 | E7: Deutlich negative Wirkung.
A8: -1 | B8: Schwach | C8: 15 | D8: Aktives WÖk-Arbeitsmodell v1.3 | E8: Negative Wirkung.
A9: 0 | B9: Neutral | C9: 10 | D9: Aktives WÖk-Arbeitsmodell v1.3 | E9: Keine belastbare positive Netto-Wirkung.
A10: 1 | B10: Gut | C10: 5 | D10: Aktives WÖk-Arbeitsmodell v1.3 | E10: Positive Wirkung unterhalb Transformationsniveau.
A11: 2 | B11: Sehr gut | C11: 0 | D11: Aktives WÖk-Arbeitsmodell v1.3 | E11: Starke positive Wirkung.
A12: 3 | B12: Transformativ | C12: 0 | D12: Aktives WÖk-Arbeitsmodell v1.3 | E12: Systemisch transformativ; Nachweis- und Nichtkompensationsprinzip gelten weiter.
A15: Historisches Modell | B15: Bedingung | C15: Satz_pct | D15: Status
A16: Fünfklassenmodell 2025 | B16: Schädlich / mindestens ein Feld negativ | C16: 25 | D16: Historische Referenz – nicht aktiv
A17: Fünfklassenmodell 2025 | B17: Neutral | C17: 19 | D17: Historische Referenz – nicht aktiv
A18: Fünfklassenmodell 2025 | B18: Gut | C18: 12 | D18: Historische Referenz – nicht aktiv
A19: Fünfklassenmodell 2025 | B19: Sehr gut | C19: 5 | D19: Historische Referenz – nicht aktiv
A20: Fünfklassenmodell 2025 | B20: Transformativ | C20: 0 | D20: Historische Referenz – nicht aktiv
A22: Governance-Hinweis: Eine steuerliche Zuordnung darf nur erfolgen, wenn Messwert, Systemgrenze, Quelle, Datenstand und erforderliche Assurance vorliegen. Ein Score von +2 oder +3 hebt negative rote Linien in anderen Wirkungsfeldern nicht auf.

Sheet 05_Changelog
A1: 05 · Changelog v1.2 → v1.4 FINAL
A2: Nachvollziehbare Änderungen an Datenmodell, Scoring, Quellen, Governance, Terminologie und Transparenz.
A4: Change_ID | B4: Bereich | C4: Änderungstyp | D4: Vorher | E4: Nachher | F4: Begründung | G4: Status
A5: CH-001 | B5: Scorecards | C5: Fehlerkorrektur | D5: Leere Messwerte wurden als 0 interpretiert. | E5: Leere Eingaben bleiben unbewertet. | F5: Datenlücken dürfen keinen Score oder Steuersatz erzeugen. | G5: Umgesetzt
A6: CH-002 | B6: Scoring | C6: Fehlerkorrektur | D6: 320 Zeilen verwiesen auf fehlende Archetypen. | E6: Alle 621 Items sind einer von 28 dokumentierten Regeln zugeordnet. | F6: Vermeidung von #N/A und transparente Regelpflege. | G6: Umgesetzt
A7: CH-003 | B7: FinalScore | C7: Fehlerkorrektur | D7: Benchmark wurde bei vorhandenem Archetyp regelmäßig ignoriert. | E7: FinalScore ist das Minimum aller vorhandenen Teilbewertungen. | F7: Konservative Nichtkompensations- und Vorsorgelogik. | G7: Umgesetzt
A8: CH-004 | B8: Benchmarks | C8: Strukturänderung | D8: Generierte Schwellenwerte erschienen als Branchenbenchmarks. | E8: Aktive validierte Benchmarks und Legacy-Rechenwerte sind strikt getrennt. | F8: Keine Scheingenauigkeit oder falsche Quellenbehauptung. | G8: Umgesetzt
A9: CH-005 | B9: Qualitative Regeln | C9: Governance | D9: Qualitative Texte waren nicht operationalisiert. | E9: Assurance-Score und Kriterienkatalog werden explizit verlangt. | F9: Qualitative Wirkung braucht Evidenz und Prüfbarkeit. | G9: Umgesetzt
A10: CH-006 | B10: Rechtsgrenzen | C10: Methodenkorrektur | D10: Einheit und Definition passten nicht zur Prozent-vom-Grenzwert-Regel. | E10: Bewertet wird Messwert ÷ anwendbarer Grenzwert × 100. | F10: Rechts- und Genehmigungsgrenzen müssen fallbezogen parametrisiert werden. | G10: Umgesetzt
A11: CH-007 | B11: NACE | C11: Versionierung | D11: NACE war nicht versioniert. | E11: Legacy-Zuordnung bleibt erhalten; Migration auf NACE Rev. 2.1 wird ausgewiesen. | F11: Klassifikationsänderungen dürfen nicht unsichtbar bleiben. | G11: Umgesetzt
A12: CH-008 | B12: Quellen | C12: Strukturänderung | D12: Messstandards und Schwellenquellen waren vermischt. | E12: Quellenfunktion, Quellenstatus und Source_IDs werden getrennt geführt. | F12: Ein Messstandard belegt nicht automatisch einen Grenzwert. | G12: Umgesetzt
A13: CH-009 | B13: Register | C13: Erweiterung | D13: Systemgrenze, Datenqualität, Assurance und Gültigkeit fehlten. | E13: Pflichtfelder wurden ergänzt. | F13: Auditierbarkeit und spätere Automatisierung. | G13: Umgesetzt
A14: CH-010 | B14: Fachlogik | C14: Qualitätssicherung | D14: Generische Schablonenfehler waren unsichtbar. | E14: Fachlogik_Status, Prüfpriorität und Prüfhinweis kennzeichnen offene Punkte. | F14: Schablonenabweichungen dürfen nicht stillschweigend fortgeschrieben werden. | G14: Umgesetzt
A15: CH-011 | B15: Tarifmodell | C15: Versionierung | D15: Mehrere historische Tarifmodelle standen nebeneinander. | E15: Aktives v1.3-Arbeitsmodell wird klar von historischen Varianten getrennt. | F15: Keine Verwechslung mit geltendem Recht. | G15: Umgesetzt
... A23: CH-019 | B23: Version | C23: Release | D23: v1.3 war geprüfte Arbeits- und Governance-Fassung. | E23: v1.4 FINAL ist die führende technische Registerfassung ab 16.08.2026. | F23: FINAL bezeichnet den führenden Release-Stand, nicht die externe Validierung aller offenen Kalibrierungen. | G23: Umgesetzt

Sheet 06_Scorecards
A1: 06 · Scorecards – Eingabe und Bewertung
A2: Blaue Spalten sind Eingaben. Leere Messwerte erzeugen keinen Score. FinalScore = strengstes vorhandenes Ergebnis aus AutoScore, aktivem BenchmarkScore und Assurance-Score. v1.4: SDG+ explizit gekennzeichnet; Rechenlogik unverändert.
A4: WOK_ID | B4: SDG_or_SDGplus | C4: Target/Unterziel | D4: Indikatorfamilie | E4: Item | F4: Einheit | G4: Polarity | H4: Rule_ID | I4: Regeltyp | J4: Messwert | K4: Assurance_Score | L4: Nachweis/Quelle | M4: Datenstand | N4: AutoScore | O4: BenchmarkScore | P4: FinalScore | Q4: Steuerklasse | R4: Steuersatz_pct | S4: Datenstatus | T4: Prüfhinweis | U4: Schwellen | V4: Quelle_detail | W4: Benchmarkstatus | X4: Quellenstatus | Y4: Prüfpriorität | Z4: Regelstatus | AA4: Systemgrenze | AB4: Datenqualitätsanforderung | AC4: Assurance_Anforderung
A5: WOK-S-101 | B5: SDG 1 – Keine Armut | C5: 1.2 | D5: Faire Arbeit & Einkommen | E5: Faire Arbeit & Einkommen – Living Wage | F5: % Beschäftigte | G5: higher_is_better | H5: R27 | I5: NUM_HIGH | N5: =IF($J5="","",IF($J5<40,-3,IF($J5<60,-2,IF($J5<80,0,IF($J5<95,2,3))))) | O5: =IF($J5="","",IF(OR('02_Benchmarks'!$P5<>"Aktiv",COUNT('02_Benchmarks'!$J5:$M5)<4),"",IF($G5="lower_is_better",IF($J5<='02_Benchmarks'!$J5,3,IF($J5<'02_Benchmarks'!$K5,2,IF($J5<='02_Benchmarks'!$L5,0,IF($J5<='02_Benchmarks'!$M5,-2,-3)))),IF($J5>='02_Benchmarks'!$J5,3,IF($J5>'02_Benchmarks'!$K5,2,IF($J5>='02_Benchmarks'!$L5,0,IF($J5>='02_Benchmarks'!$M5,-2,-3))))))) | P5: =IF(COUNT($N5:$O5)+IF(ISNUMBER($K5),1,0)=0,"",MIN($N5:$O5,$K5)) | Q5: =IF($P5="","",INDEX('04_Tarifmodell'!$B$6:$B$12,$P5+4)) | R5: =IF($P5="","",INDEX('04_Tarifmodell'!$C$6:$C$12,$P5+4)) | S5: =IF(OR($I5="QUALITATIVE",$I5="MANUAL_HYBRID"),IF($K5="","Assurance-Score fehlt","Assurance-bewertet"),IF($I5="BENCHMARK",IF($W5<>"Aktiv",IF($K5="","Benchmark fehlt","Assurance-bewertet"),IF($J5="","Messwert fehlt",IF($P5="","Nicht bewertbar","Berechnet"))),IF(AND($J5="",$K5<>""),"Nur Assurance-Score",IF($J5="","Messwert fehlt",IF($P5="","Nicht bewertbar",IF($P5<=-2,"Kritische Wirkung / Prüfung","Berechnet")))))) -> Messwert fehlt | T5: Vollständige fünfstufige numerische Regel. | U5: ≥95:+3; 80–94:+2; 60–79:0; 40–59:‑2; <40:‑3 | V5: ESRS S1, GRI 401/403/405/406, ILO | W5: ='02_Benchmarks'!$P5 -> Optional – kein aktiver Benchmark | X5: Messgrundlage belegt; Schwellenkalibrierung offen | Y5: Mittel | Z5: Arbeitskalibrierung – fachlich zu validieren | AA5: Eigene Belegschaft/Organisation; FTE, Beschäftigtengruppe und Zeitraum | AB5: Primärdaten bevorzugt; Sekundärdaten nur transparent und versioniert; Methode und Systemgrenze dokumentieren | AC5: Limited Assurance; risikobasiert höhere Prüftiefe
A6: WOK-S-102 | B6: SDG 1 – Keine Armut | C6: 1.2 | D6: Faire Arbeit & Einkommen | E6: Faire Arbeit & Einkommen – Tarifbindung | F6: % | G6: higher_is_better | H6: R26 | I6: NUM_HIGH | N6: =IF($J6="","",IF($J6<30,-3,IF($J6<50,-2,IF($J6<70,0,IF($J6<90,2,3))))) | O6: =IF($J6="","",IF(OR('02_Benchmarks'!$P6<>"Aktiv",COUNT('02_Benchmarks'!$J6:$M6)<4),"",IF($G6="lower_is_better",IF($J6<='02_Benchmarks'!$J6,3,IF($J6<'02_Benchmarks'!$K6,2,IF($J6<='02_Benchmarks'!$L6,0,IF($J6<='02_Benchmarks'!$M6,-2,-3)))),IF($J6>='02_Benchmarks'!$J6,3,IF($J6>'02_Benchmarks'!$K6,2,IF($J6>='02_Benchmarks'!$L6,0,IF($J6>='02_Benchmarks'!$M6,-2,-3))))))) | P6: =IF(COUNT($N6:$O6)+IF(ISNUMBER($K6),1,0)=0,"",MIN($N6:$O6,$K6)) | Q6: =IF($P6="","",INDEX('04_Tarifmodell'!$B$6:$B$12,$P6+4)) | R6: =IF($P6="","",INDEX('04_Tarifmodell'!$C$6:$C$12,$P6+4)) | S6: =IF(OR($I6="QUALITATIVE",$I6="MANUAL_HYBRID"),IF($K6="","Assurance-Score fehlt","Assurance-bewertet"),IF($I6="BENCHMARK",IF($W6<>"Aktiv",IF($K6="","Benchmark fehlt","Assurance-bewertet"),IF($J6="","Messwert fehlt",IF($P6="","Nicht bewertbar","Berechnet"))),IF(AND($J6="",$K6<>""),"Nur Assurance-Score",IF($J6="","Messwert fehlt",IF($P6="","Nicht bewertbar",IF($P6<=-2,"Kritische Wirkung / Prüfung","Berechnet")))))) -> Messwert fehlt | T6: Vollständige fünfstufige numerische Regel. | U6: ≥90:+3; 70–89:+2; 50–69:0; 30–49:‑2; <30:‑3 | V6: ESRS S1, GRI 401/403/405/406, ILO | W6: ='02_Benchmarks'!$P6 -> Optional – kein aktiver Benchmark | X6: Messgrundlage belegt; Schwellenkalibrierung offen | Y6: Mittel | Z6: Arbeitskalibrierung – fachlich zu validieren | AA6: Eigene Belegschaft/Organisation; FTE, Beschäftigtengruppe und Zeitraum | AB6: Primärdaten bevorzugt; Sekundärdaten nur transparent und versioniert; Methode und Systemgrenze dokumentieren | AC6: Limited Assurance; risikobasiert höhere Prüftiefe
A7: WOK-S-103 | B7: SDG 1 – Keine Armut | C7: 1.2 | D7: Faire Arbeit & Einkommen | E7: Faire Arbeit & Einkommen – LTIFR | F7: Unfälle/Mio Std. | G7: lower_is_better | H7: R02 | I7: NUM_LOW | N7: =IF($J7="","",IF($J7<=0,3,IF($J7<=1,2,IF($J7<=3,0,IF($J7<=5,-2,-3))))) | O7: =IF($J7="","",IF(OR('02_Benchmarks'!$P7<>"Aktiv",COUNT('02_Benchmarks'!$J7:$M7)<4),"",IF($G7="lower_is_better",IF($J7<='02_Benchmarks'!$J7,3,IF($J7<'02_Benchmarks'!$K7,2,IF($J7<='02_Benchmarks'!$L7,0,IF($J7<='02_Benchmarks'!$M7,-2,-3)))),IF($J7>='02_Benchmarks'!$J7,3,IF($J7>'02_Benchmarks'!$K7,2,IF($J7>='02_Benchmarks'!$L7,0,IF($J7>='02_Benchmarks'!$M7,-2,-3))))))) | P7: =IF(COUNT($N7:$O7)+IF(ISNUMBER($K7),1,0)=0,"",MIN($N7:$O7,$K7)) | Q7: =IF($P7="","",INDEX('04_Tarifmodell'!$B$6:$B$12,$P7+4)) | R7: =IF($P7="","",INDEX('04_Tarifmodell'!$C$6:$C$12,$P7+4)) | S7: =IF(OR($I7="QUALITATIVE",$I7="MANUAL_HYBRID"),IF($K7="","Assurance-Score fehlt","Assurance-bewertet"),IF($I7="BENCHMARK",IF($W7<>"Aktiv",IF($K7="","Benchmark fehlt","Assurance-bewertet"),IF($J7="","Messwert fehlt",IF($P7="","Nicht bewertbar","Berechnet"))),IF(AND($J7="",$K7<>""),"Nur Assurance-Score",IF($J7="","Messwert fehlt",IF($P7="","Nicht bewertbar",IF($P7<=-2,"Kritische Wirkung / Prüfung","Berechnet")))))) -> Messwert fehlt | T7: Vollständige fünfstufige numerische Regel. | U7: 0:+3; ≤1:+2; ≤3:0; ≤5:‑2; >5:‑3 | V7: ESRS S1, GRI 401/403/405/406, ILO | W7: ='02_Benchmarks'!$P7 -> Optional – kein aktiver Benchmark | X7: Messgrundlage belegt; Schwellenkalibrierung offen | Y7: Mittel | Z7: Arbeitskalibrierung – fachlich zu validieren | AA7: Eigene Belegschaft/Organisation; FTE, Beschäftigtengruppe und Zeitraum | AB7: Primärdaten bevorzugt; Sekundärdaten nur transparent und versioniert; Methode und Systemgrenze dokumentieren | AC7: Limited Assurance; risikobasiert höhere Prüftiefe
A8: WOK-S-104 | B8: SDG 1 – Keine Armut | C8: 1.3 | D8: Sozialschutz & Benefits | E8: Sozialschutz & Benefits – Living Wage | F8: % Beschäftigte | G8: higher_is_better | H8: R27 | I8: NUM_HIGH | N8: =IF($J8="","",IF($J8<40,-3,IF($J8<60,-2,IF($J8<80,0,IF($J8<95,2,3))))) | O8: =IF($J8="","",IF(OR('02_Benchmarks'!$P8<>"Aktiv",COUNT('02_Benchmarks'!$J8:$M8)<4),"",IF($G8="lower_is_better",IF($J8<='02_Benchmarks'!$J8,3,IF($J8<'02_Benchmarks'!$K8,2,IF($J8<='02_Benchmarks'!$L8,0,IF($J8<='02_Benchmarks'!$M8,-2,-3)))),IF($J8>='02_Benchmarks'!$J8,3,IF($J8>'02_Benchmarks'!$K8,2,IF($J8>='02_Benchmarks'!$L8,0,IF($J8>='02_Benchmarks'!$M8,-2,-3))))))) | P8: =IF(COUNT($N8:$O8)+IF(ISNUMBER($K8),1,0)=0,"",MIN($N8:$O8,$K8)) | Q8: =IF($P8="","",INDEX('04_Tarifmodell'!$B$6:$B$12,$P8+4)) | R8: =IF($P8="","",INDEX('04_Tarifmodell'!$C$6:$C$12,$P8+4)) | S8: =IF(OR($I8="QUALITATIVE",$I8="MANUAL_HYBRID"),IF($K8="","Assurance-Score fehlt","Assurance-bewertet"),IF($I8="BENCHMARK",IF($W8<>"Aktiv",IF($K8="","Benchmark fehlt","Assurance-bewertet"),IF($J8="","Messwert fehlt",IF($P8="","Nicht bewertbar","Berechnet"))),IF(AND($J8="",$K8<>""),"Nur Assurance-Score",IF($J8="","Messwert fehlt",IF($P8="","Nicht bewertbar",IF($P8<=-2,"Kritische Wirkung / Prüfung","Berechnet")))))) -> Messwert fehlt | T8: Vollständige fünfstufige numerische Regel. | U8: ≥95:+3; 80–94:+2; 60–79:0; 40–59:‑2; <40:‑3 | V8: ESRS S1, GRI 401/403/405/406, ILO | W8: ='02_Benchmarks'!$P8 -> Optional – kein aktiver Benchmark | X8: Messgrundlage belegt; Schwellenkalibrierung offen | Y8: Mittel | Z8: Arbeitskalibrierung – fachlich zu validieren | AA8: Eigene Belegschaft/Organisation; FTE, Beschäftigtengruppe und Zeitraum | AB8: Primärdaten bevorzugt; Sekundärdaten nur transparent und versioniert; Methode und Systemgrenze dokumentieren | AC8: Limited Assurance; risikobasiert höhere Prüftiefe
A9: WOK-S-105 | B9: SDG 1 – Keine Armut | C9: 1.3 | D9: Sozialschutz & Benefits | E9: Sozialschutz & Benefits – Tarifbindung | F9: % | G9: higher_is_better | H9: R26 | I9: NUM_HIGH | N9: =IF($J9="","",IF($J9<30,-3,IF($J9<50,-2,IF($J9<70,0,IF($J9<90,2,3))))) | O9: =IF($J9="","",IF(OR('02_Benchmarks'!$P9<>"Aktiv",COUNT('02_Benchmarks'!$J9:$M9)<4),"",IF($G9="lower_is_better",IF($J9<='02_Benchmarks'!$J9,3,IF($J9<'02_Benchmarks'!$K9,2,IF($J9<='02_Benchmarks'!$L9,0,IF($J9<='02_Benchmarks'!$M9,-2,-3)))),IF($J9>='02_Benchmarks'!$J9,3,IF($J9>'02_Benchmarks'!$K9,2,IF($J9>='02_Benchmarks'!$L9,0,IF($J9>='02_Benchmarks'!$M9,-2,-3))))))) | P9: =IF(COUNT($N9:$O9)+IF(ISNUMBER($K9),1,0)=0,"",MIN($N9:$O9,$K9)) | Q9: =IF($P9="","",INDEX('04_Tarifmodell'!$B$6:$B$12,$P9+4)) | R9: =IF($P9="","",INDEX('04_Tarifmodell'!$C$6:$C$12,$P9+4)) | S9: =IF(OR($I9="QUALITATIVE",$I9="MANUAL_HYBRID"),IF($K9="","Assurance-Score fehlt","Assurance-bewertet"),IF($I9="BENCHMARK",IF($W9<>"Aktiv",IF($K9="","Benchmark fehlt","Assurance-bewertet"),IF($J9="","Messwert fehlt",IF($P9="","Nicht bewertbar","Berechnet"))),IF(AND($J9="",$K9<>""),"Nur Assurance-Score",IF($J9="","Messwert fehlt",IF($P9="","Nicht bewertbar",IF($P9<=-2,"Kritische Wirkung / Prüfung","Berechnet")))))) -> Messwert fehlt | T9: Vollständige fünfstufige numerische Regel. | U9: ≥90:+3; 70–89:+2; 50–69:0; 30–49:‑2; <30:‑3 | V9: ESRS S1, GRI 401/403/405/406, ILO | W9: ='02_Benchmarks'!$P9 -> Optional – kein aktiver Benchmark | X9: Messgrundlage belegt; Schwellenkalibrierung offen | Y9: Mittel | Z9: Arbeitskalibrierung – fachlich zu validieren | AA9: Eigene Belegschaft/Organisation; FTE, Beschäftigtengruppe und Zeitraum | AB9: Primärdaten bevorzugt; Sekundärdaten nur transparent und versioniert; Methode und Systemgrenze dokumentieren | AC9: Limited Assurance; risikobasiert höhere Prüftiefe
A10: WOK-S-106 | B10: SDG 1 – Keine Armut | C10: 1.3 | D10: Sozialschutz & Benefits | E10: Sozialschutz & Benefits – LTIFR | F10: Unfälle/Mio Std. | G10: lower_is_better | H10: R02 | I10: NUM_LOW | N10: =IF($J10="","",IF($J10<=0,3,IF($J10<=1,2,IF($J10<=3,0,IF($J10<=5,-2,-3))))) | O10: =IF($J10="","",IF(OR('02_Benchmarks'!$P10<>"Aktiv",COUNT('02_Benchmarks'!$J10:$M10)<4),"",IF($G10="lower_is_better",IF($J10<='02_Benchmarks'!$J10,3,IF($J10<'02_Benchmarks'!$K10,2,IF($J10<='02_Benchmarks'!$L10,0,IF($J10<='02_Benchmarks'!$M10,-2,-3)))),IF($J10>='02_Benchmarks'!$J10,3,IF($J10>'02_Benchmarks'!$K10,2,IF($J10>='02_Benchmarks'!$L10,0,IF($J10>='02_Benchmarks'!$M10,-2,-3))))))) | P10: =IF(COUNT($N10:$O10)+IF(ISNUMBER($K10),1,0)=0,"",MIN($N10:$O10,$K10)) | Q10: =IF($P10="","",INDEX('04_Tarifmodell'!$B$6:$B$12,$P10+4)) | R10: =IF($P10="","",INDEX('04_Tarifmodell'!$C$6:$C$12,$P10+4)) | S10: =IF(OR($I10="QUALITATIVE",$I10="MANUAL_HYBRID"),IF($K10="","Assurance-Score fehlt","Assurance-bewertet"),IF($I10="BENCHMARK",IF($W10<>"Aktiv",IF($K10="","Benchmark fehlt","Assurance-bewertet"),IF($J10="","Messwert fehlt",IF($P10="","Nicht bewertbar","Berechnet"))),IF(AND($J10="",$K10<>""),"Nur Assurance-Score",IF($J10="","Messwert fehlt",IF($P10="","Nicht bewertbar",IF($P10<=-2,"Kritische Wirkung / Prüfung","Berechnet")))))) -> Messwert fehlt | T10: Vollständige fünfstufige numerische Regel. | U10: 0:+3; ≤1:+2; ≤3:0; ≤5:‑2; >5:‑3 | V10: ESRS S1, GRI 401/403/405/406, ILO | W10: ='02_Benchmarks'!$P10 -> Optional – kein aktiver Benchmark | X10: Messgrundlage belegt; Schwellenkalibrierung offen | Y10: Mittel | Z10: Arbeitskalibrierung – fachlich zu validieren | AA10: Eigene Belegschaft/Organisation; FTE, Beschäftigtengruppe und Zeitraum | AB10: Primärdaten bevorzugt; Sekundärdaten nur transparent und versioniert; Methode und Systemgrenze dokumentieren | AC10: Limited Assurance; risikobasiert höhere Prüftiefe
A11: WOK-SC-101 | B11: SDG 1 – Keine Armut | C11: 1.2 | D11: Living‑Wage in Lieferkette | E11: Living‑Wage in Lieferkette – ESG‑Spend‑Coverage | F11: % | G11: higher_is_better | H11: R26 | I11: NUM_HIGH | N11: =IF($J11="","",IF($J11<30,-3,IF($J11<50,-2,IF($J11<70,0,IF($J11<90,2,3))))) | O11: =IF($J11="","",IF(OR('02_Benchmarks'!$P11<>"Aktiv",COUNT('02_Benchmarks'!$J11:$M11)<4),"",IF($G11="lower_is_better",IF($J11<='02_Benchmarks'!$J11,3,IF($J11<'02_Benchmarks'!$K11,2,IF($J11<='02_Benchmarks'!$L11,0,IF($J11<='02_Benchmarks'!$M11,-2,-3)))),IF($J11>='02_Benchmarks'!$J11,3,IF($J11>'02_Benchmarks'!$K11,2,IF($J11>='02_Benchmarks'!$L11,0,IF($J11>='02_Benchmarks'!$M11,-2,-3))))))) | P11: =IF(COUNT($N11:$O11)+IF(ISNUMBER($K11),1,0)=0,"",MIN($N11:$O11,$K11)) | Q11: =IF($P11="","",INDEX('04_Tarifmodell'!$B$6:$B$12,$P11+4)) | R11: =IF($P11="","",INDEX('04_Tarifmodell'!$C$6:$C$12,$P11+4)) | S11: =IF(OR($I11="QUALITATIVE",$I11="MANUAL_HYBRID"),IF($K11="","Assurance-Score fehlt","Assurance-bewertet"),IF($I11="BENCHMARK",IF($W11<>"Aktiv",IF($K11="","Benchmark fehlt","Assurance-bewertet"),IF($J11="","Messwert fehlt",IF($P11="","Nicht bewertbar","Berechnet"))),IF(AND($J11="",$K11<>""),"Nur Assurance-Score",IF($J11="","Messwert fehlt",IF($P11="","Nicht bewertbar",IF($P11<=-2,"Kritische Wirkung / Prüfung","Berechnet")))))) -> Messwert fehlt | T11: Vollständige fünfstufige numerische Regel. | U11: ≥90:+3; 70–89:+2; 50–69:0; 30–49:‑2; <30:‑3 | V11: ESRS S2, GRI 308/414, OECD Due Diligence | W11: ='02_Benchmarks'!$P11 -> Optional – kein aktiver Benchmark | X11: Messgrundlage belegt; Schwellenkalibrierung offen | Y11: Mittel | Z11: Arbeitskalibrierung – fachlich zu validieren | AA11: Vorgelagerte Lieferkette; relevante Tier-Stufen und Beschaffungsvolumen | AB11: Primärdaten bevorzugt; Sekundärdaten nur transparent und versioniert; Methode und Systemgrenze dokumentieren | AC11: Limited Assurance; risikobasiert höhere Prüftiefe
A12: WOK-SC-102 | B12: SDG 1 – Keine Armut | C12: 1.2 | D12: Living‑Wage in Lieferkette | E12: Living‑Wage in Lieferkette – Kinder/Zwangsarbeit | F12: % Lieferanten | G12: higher_is_better | H12: R28 | I12: NUM_HIGH | N12: =IF($J12="","",IF($J12<50,-3,IF($J12<75,-2,IF($J12<90,0,IF($J12<98,2,3))))) | O12: =IF($J12="","",IF(OR('02_Benchmarks'!$P12<>"Aktiv",COUNT('02_Benchmarks'!$J12:$M12)<4),"",IF($G12="lower_is_better",IF($J12<='02_Benchmarks'!$J12,3,IF($J12<'02_Benchmarks'!$K12,2,IF($J12<='02_Benchmarks'!$L12,0,IF($J12<='02_Benchmarks'!$M12,-2,-3)))),IF($J12>='02_Benchmarks'!$J12,3,IF($J12>'02_Benchmarks'!$K12,2,IF($J12>='02_Benchmarks'!$L12,0,IF($J12>='02_Benchmarks'!$M12,-2,-3))))))) | P12: =IF(COUNT($N12:$O12)+IF(ISNUMBER($K12),1,0)=0,"",MIN($N12:$O12,$K12)) | Q12: =IF($P12="","",INDEX('04_Tarifmodell'!$B$6:$B$12,$P12+4)) | R12: =IF($P12="","",INDEX('04_Tarifmodell'!$C$6:$C$12,$P12+4)) | S12: =IF(OR($I12="QUALITATIVE",$I12="MANUAL_HYBRID"),IF($K12="","Assurance-Score fehlt","Assurance-bewertet"),IF($I12="BENCHMARK",IF($W12<>"Aktiv",IF($K12="","Benchmark fehlt","Assurance-bewertet"),IF($J12="","Messwert fehlt",IF($P12="","Nicht bewertbar","Berechnet"))),IF(AND($J12="",$K12<>""),"Nur Assurance-Score",IF($J12="","Messwert fehlt",IF($P12="","Nicht bewertbar",IF($P12<=-2,"Kritische Wirkung / Prüfung","Berechnet")))))) -> Messwert fehlt | T12: Vollständige fünfstufige numerische Regel. | U12: ≥98:+3; 90–97:+2; 75–89:0; 50–74:‑2; <50:‑3 | V12: ESRS S2, GRI 308/414, OECD Due Diligence | W12: ='02_Benchmarks'!$P12 -> Optional – kein aktiver Benchmark | X12: Messgrundlage belegt; Schwellenkalibrierung offen | Y12: Mittel | Z12: Arbeitskalibrierung – fachlich zu validieren | AA12: Vorgelagerte Lieferkette; relevante Tier-Stufen und Beschaffungsvolumen | AB12: Primärdaten bevorzugt; Sekundärdaten nur transparent und versioniert; Methode und Systemgrenze dokumentieren | AC12: Limited Assurance; risikobasiert höhere Prüftiefe
A13: WOK-SC-103 | B13: SDG 1 – Keine Armut | C13: 1.2 | D13: Living‑Wage in Lieferkette | E13: Living‑Wage in Lieferkette – Scope‑3 Daten | F13: % Kategorien | G13: higher_is_better | H13: R23 | I13: NUM_HIGH | N13: =IF($J13="","",IF($J13<20,-3,IF($J13<40,-2,IF($J13<60,0,IF($J13<80,2,3))))) | O13: =IF($J13="","",IF(OR('02_Benchmarks'!$P13<>"Aktiv",COUNT('02_Benchmarks'!$J13:$M13)<4),"",IF($G13="lower_is_better",IF($J13<='02_Benchmarks'!$J13,3,IF($J13<'02_Benchmarks'!$K13,2,IF($J13<='02_Benchmarks'!$L13,0,IF($J13<='02_Benchmarks'!$M13,-2,-3)))),IF($J13>='02_Benchmarks'!$J13,3,IF($J13>'02_Benchmarks'!$K13,2,IF($J13>='02_Benchmarks'!$L13,0,IF($J13>='02_Benchmarks'!$M13,-2,-3))))))) | P13: =IF(COUNT($N13:$O13)+IF(ISNUMBER($K13),1,0)=0,"",MIN($N13:$O13,$K13)) | Q13: =IF($P13="","",INDEX('04_Tarifmodell'!$B$6:$B$12,$P13+4)) | R13: =IF($P13="","",INDEX('04_Tarifmodell'!$C$6:$C$12,$P13+4)) | S13: =IF(OR($I13="QUALITATIVE",$I13="MANUAL_HYBRID"),IF($K13="","Assurance-Score fehlt","Assurance-bewertet"),IF($I13="BENCHMARK",IF($W13<>"Aktiv",IF($K13="","Benchmark fehlt","Assurance-bewertet"),IF($J13="","Messwert fehlt",IF($P13="","Nicht bewertbar","Berechnet"))),IF(AND($J13="",$K13<>""),"Nur Assurance-Score",IF($J13="","Messwert fehlt",IF($P13="","Nicht bewertbar",IF($P13<=-2,"Kritische Wirkung / Prüfung","Berechnet")))))) -> Messwert fehlt | T13: Vollständige fünfstufige numerische Regel. | U13: ≥80:+3; 60–79:+2; 40–59:0; 20–39:‑2; <20:‑3 | V13: ESRS E1, GHG Protocol (Corporate/Scope 1–3), ISO 14064/14067 | W13: ='02_Benchmarks'!$P13 -> Optional – kein aktiver Benchmark | X13: Messgrundlage belegt; Schwellenkalibrierung offen | Y13: Mittel | Z13: Arbeitskalibrierung – fachlich zu validieren | AA13: Vorgelagerte Lieferkette; relevante Tier-Stufen und Beschaffungsvolumen | AB13: Primärdaten bevorzugt; Sekundärdaten nur transparent und versioniert; Methode und Systemgrenze dokumentieren | AC13: Limited Assurance; risikobasiert höhere Prüftiefe
